Workbook

Sheet Sessions
A1: SPEAKERS INFORMATION | AT1: SPEAKERS PREFERENCES | BI1: FOLLOW-UP | BM1: Travel information - confirmed | CF1: APPROVALS
A2: Date | B2: Slot | C2: Estimated arrival date | D2: Estimated departure date | E2: Index unique | F2: Title | G2: Thematic clusters | H2: Format | I2: Merged sessions | J2: Merged lead? | K2: Lead partner organisation name | L2: Lead partner organisation country of origin | M2: Associated partners | N2: Coordinator | O2: Email address | P2: Company name | Q2: Job title | R2: Speakers | S2: Answered | T2: Form sent to speakers/reminder to SC | U2: Do any of your speakers require travel coverage? | V2: Number of speakers needed for Travel | W2: Travel - Speaker 1 - Name | X2: Travel - Speaker 1 - Name + last name | Y2: Travel - Speaker 1 - Email address | Z2: Travel - Speaker 2 - Name | AA2: Travel - Speaker 2 - Name + last name | AB2: Travel - Speaker 2 - Email address | AC2: Travel - Speaker 3 - Name | AD2: Travel - Speaker 3 - Name + last name | AE2: Travel - Speaker 3 - Email address | AF2: Do any of your speakers require accommodation coverage? | AG2: Number of speakers needed for Accommodation | AH2: Accomodation - Speaker 1 - Name | AI2: Accomodation - Speaker 1 - Last name | AJ2: Accomodation - Speaker 1 - Email address | AK2: Accomodation - Speaker 2 - Name | AL2: Accomodation - Speaker 2 - Last name | AM2: Accomodation - Speaker 2 - Email address | AN2: Accomodation - Speaker 3 - Name | AO2: Accomodation - Speaker 3 - Last name | AP2: Accomodation - Speaker 3 - Email address | AQ2: Additional comments | AR2: Email follow up - Responses | AS2: Comments VO | AT2: First Name | AU2: Last name | AV2: Email address | AW2: Phone number | AX2: Date and time of your speaking slot | AY2: Travel needed | AZ2: Preferred mode of transport | BA2: City of departure | BB2: Date of departure | BC2: Time of departure | BD2: Return city | BE2: Preferred date of return | BF2: Preferred time of return | BG2: Accommodation needed | BH2: Additional comments | BI2: Agency sent proposal | BJ2: Guest confirmed proposal | BK2: Travel booked | BL2: Travel tickets sent to guest | BM2: Origin City (to Brussels) | BN2: Flight/Train | BO2: Date of departure | BP2: Flight/Train time | BQ2: Flight number/Train | BR2: Return City (from Brussels) | BS2: Date of return | BT2: Flight/Train time | BU2: Flight number/Train | BV2: Flight/Train cost | BW2: 45943 | BX2: 45944 | BY2: 45945 | BZ2: Check-in date | CA2: Check out date | CB2: Hotel name | CC2: Hotel nights | CD2: Hotel cost, €, excl. VAT | CE2: Total cost, € | CF2: Client's approval needed | CG2: Client's approval received | CH2: Approval reason
A3: 45944 | B3: 11:30 - 13:00 | C3: 45943 | D3: 45945 | E3: 1965 | F3: Enabled by Design: Building Risk Communication for People with Disabilities | G3: Cities building tomorrow | H3: Interactive session | J3: No | K3: Climate KIC International Foundation | L3: Netherlands | N3: Michelle Zheng ; Cristobal Reveco | O3: michelle.zheng@climate-kic.org; cristobal.reveco@hereon.de | P3: EIT Climate-KIC | Q3: Officer | R3: Zdeněk HŘIB - - - - ; Štěpán Vizina - - - - ; Georgia KALOUSI - - - - | S3: Yes | T3: YES | U3: No | V3: 0 | AF3: No | AG3: 0 | AQ3: No comment | AY3: No | BG3: No
A4: 45944 | B4: 09:30 - 10:30 | C4: 45943 | D4: 45945 | E4: 1969 | F4: Cities leveraging data for impact – showcasing real-life success stories | G4: Cities building tomorrow | H4: Workshop | I4: 19692590 | J4: Yes | K4: Publications Office of the European Union | L4: Luxembourg | N4: Cecilia Charlier ; Dominika Uhrikova | O4: Cecilia.CHARLIER@publications.europa.eu ; Dominika.UHRIKOVA@ec.europa.eu | P4: Publications Office of the European Union | Q4: Assistant | R4: Mani Dhingra - Dublin City Council - Programme Manager - - ; Carlos MARTINS FERREIRA - Publications Office of the European Union - Assistant - - | S4: yes | T4: YES | U4: Yes | V4: 2 | W4: Mani | X4: Dhingra | Y4: mani@smartd8.ie | Z4: Olaf | AA4: Osica | AB4: olaf.osica@gmail.com | AF4: Yes | AG4: 2 | AH4: Mani | AI4: Dhingra | AJ4: mani@smartd8.ie | AK4: Olaf | AL4: Osica | AM4: olaf.osica@gmail.com | AQ4: We have only 2 speakers to reimburse. As the system didn't allow to submit the form without filling in the 3rd line in each table, I put "n/a" in the third line of each table to say that line is not applicable. | AR4: positive | AS4: They will need t&a for their speaker | AT4: Mani | AU4: Dhingra | AV4: mani@smartd8.ie | AW4: 353892541846 | AX4: 14th Oct 9.30 to 10.30 am | AY4: Yes | AZ4: I prefer to travel by plane | BA4: Dublin | BB4: 45943 | BC4: Between 1 and 4 pm | BD4: Dublin | BE4: 45945 | BF4: Between 12 and 4 pm | BG4: Yes | BH4: Because of strike i would like to come a day early and leave a day later ti avoid 14th October travel day. | BI4: YES | BJ4: YES | BK4: YES | BL4: YES | BM4: Dublin | BN4: Flight | BO4: 45943 | BP4: 0.64236111 | BQ4: fr1452 | BR4: Dublin | BS4: 45945 | BT4: 0.88888889 | BU4: ei639 | BV4: 259.71 | BW4: 1 | BX4: 1 | BZ4: 45943 | CA4: 45945 | CC4: =BW4+BX4+BY4 -> 2
AT5: Olaf | AU5: Osica | AV5: olaf.osica@gmail.com | AW5: 48784939432 | AX5: 14 Oct 09.30 AM | AY5: Yes | AZ5: I prefer to travel by plane | BA5: Warsaw | BB5: 45943 | BC5: 1000 | BD5: Warsaw | BE5: 45945 | BF5: 1500 | BG5: Yes | BH5: Since a national strike has been announced for the 14th of Oct I need to stay one more night after my panel. | BI5: YES | BJ5: YES | BK5: YES | BL5: YES | BM5: Warsaw | BN5: Flight | BO5: 45943 | BP5: 0.43402778 | BQ5: LO237 | BR5: Warsaw | BS5: 45945 | BT5: 0.63888889 | BU5: SN2555 | BV5: 512.02 | BW5: 1 | BX5: 1 | BZ5: 45943 | CA5: 45945 | CC5: =BW5+BX5+BY5 -> 2
A6: 45945 | B6: 11:30 - 13:00 | C6: 45943 | D6: 45945 | E6: 2026 | F6: The European Innovation Experience: A dynamic co-creative dialogue on how regional innovation boosts the Union of Skills and the twin transition | G6: Cohesion and Growth for the Future | H6: Interactive session | J6: No | K6: Hanze University of Applied Sciences | L6: Netherlands | N6: Albert Haan ; Elanna Veldkamp | O6: a.w.haan@pl.hanze.nl ; e.s.veldkamp@pl.hanze.nl | P6: Hanze University of Applied Sciences | Q6: Project Manager | R6: Svenja Tams - Hochschule Bremen - Professor - - ; Rix Groenboom - Hanze University of Applied Sciences - Professor - - ; Amir Haj-Bolouri - University West - Professor - - | S6: Yes | T6: YES | U6: Yes | V6: 3 | W6: Rix | X6: Groenboom | Y6: h.m.groenboom@pl.hanze.nl | Z6: Svenja | AA6: Tams | AB6: Svenja.Tams@hs-bremen.de | AC6: Dorina | AD6: Gjipali | AE6: dorinagjipali@uamd.edu.al | AF6: Yes | AG6: 3 | AH6: Rix | AI6: Groenboom | AJ6: h.m.groenboom@pl.hanze.nl | AK6: Svenja | AL6: Tams | AM6: Svenja.Tams@hs-bremen.de | AN6: Dorina | AO6: Gjipali | AP6: dorinagjipali@uamd.edu.al | AQ6: No comment | AS6: Groningen | AT6: Rix | AU6: Groenboom | AV6: h.m.groenboom@pl.hanze.nl | AY6: No | BB6: 45943 | BE6: 45945 | BG6: Yes | BI6: YES | BJ6: YES | BK6: YES | BL6: YES | BW6: 1 | BX6: 1 | BZ6: 45943 | CA6: 45945
AT7: Svenja | AU7: Tams | AV7: Svenja.Tams@hs-bremen.de | AW7: +49 1516 5151 748 | AX7: Wed, 15/10/2025, 11:30-13:00 CET | AY7: Yes | AZ7: I prefer to travel by train | BA7: Bremen | BB7: 45943 | BC7: 09:00 | BD7: Bremen | BE7: 45945 | BF7: 15:00 | BG7: Yes | BH7: Please book one additional night from Monday, 13.10.2025 - Tuesday, 14.10.2025. | BI7: YES | BJ7: YES | BK7: YES | BL7: YES | BM7: Bremen | BN7: train | BO7: 45943 | BP7: 0.36944444 | BR7: Bremen | BS7: 45945 | BT7: 0.68194444 | BV7: 392.59 | BW7: 1 | BX7: 1 | BZ7: 45943 | CA7: 45945 | CC7: =BW7+BX7+BY7 -> 2
AT8: Dorina | AU8: Gjipali | AV8: dorinagjipali@uamd.edu.al | AW8: 355689022333 | AX8: Wednesday, 15 October 2025 11:30 - 13:00 CET | AY8: Yes | AZ8: I prefer to travel by plane | BA8: Tirana | BB8: 45943 | BC8: Daily | BD8: Tirana | BE8: 45945 | BF8: Daily | BG8: Yes | BI8: YES | BJ8: YES | BK8: YES | BL8: YES | BM8: Tirana | BN8: Flight | BO8: 45943 | BP8: 0.39583333 | BQ8: tb2952 | BR8: Tirana | BS8: 45945 | BT8: 0.72916667 | BU8: lh5577-1453 | BV8: 487.82 | BW8: 1 | BX8: 1 | BZ8: 45943 | CA8: 45945 | CC8: =BW8+BX8+BY8 -> 2
A9: 45944 | B9: 15:30 - 16:30 | C9: 45943 | D9: 45945 | E9: 2027 | F9: Power of Territorial Cooperation: Co-creating a common and sustainable Baltic Sea Region by Macro-Regional Strategy, Interreg, Youth and Communities | G9: The Right to Stay: unlocking the potential of every territory | H9: Workshop | I9: 20272512 | J9: Yes | K9: Interreg Baltic Sea Region | L9: Germany | N9: Elena Kolosova ; Anna Galyga | O9: elena.kolosova@interreg-baltic.eu; Anna.Galyga@interreg-baltic.eu | P9: baltic.eu | Q9: Interreg Baltic Sea Region - Representative | R9: Esa Kokkonen - The Baltic Institute of Finland - Director - - ; Martin Noorkõiv - Foundation for Science and Liberal Arts Domus Dorpatensis - Director - - ; Silva Laure - The Council of the Baltic Sea States Secretariat - Officer - - | S9: After deadline-via email - request approved | T9: YES | U9: Yes | V9: 1 | W9: Silva | X9: Laure | Y9: silva.laure@gmail.com | AG9: 1 | AH9: Silva | AI9: Laure | AJ9: silva.laure@gmail.com | AT9: Silva | AU9: Laure | AV9: silva.laure@gmail.com | AW9: +371 29215900 | AX9: 14th of October, 15:30 to 16:30 | AY9: Yes | AZ9: I prefer to travel by plane | BA9: Riga | BB9: 45943 | BC9: evening | BD9: Riga | BE9: 45945 | BG9: Yes | BI9: YES | BJ9: YES | BK9: YES | BL9: YES | BM9: Riga | BN9: Flight | BO9: 45943 | BP9: 0.70486111 | BQ9: BT603 | BR9: Riga | BS9: 45945 | BT9: 0.40625 | BU9: BT602 | BV9: 251.82 | BW9: 1 | BX9: 1 | BZ9: 45943 | CA9: 45945 | CC9: =BW9+BX9+BY9 -> 2
A10: 45945 | B10: 11:30 - 12:30 | C10: 45943 | D10: 45945 | E10: 2046 | F10: Connected to stay: Investing in digital connectivity for Europe’s remote, rural and outermost regions | G10: The Right to Stay: unlocking the potential of every territory | H10: Workshop | J10: No | K10: European Broadband Competence Offices Network Support Facility | L10: Belgium | N10: Dimitra Vasilia ; Angelo Cerqueti | O10: dimitra.vasilia@broadbandeurope.eu ; angelo.cerqueti@ec.europa.eu | P10: European Commission | Q10: DG AGRI - Representative | R10: Maria-Christina MAKRANDREOU - European Commission - DG AGRI - - - ; Herve DUPUY - Health and Digital Executive Agency (HaDEA) - Head of Unit - - ; João Vaz - National Authority for Communications - ANACOM - Director - - | S10: yes | T10: YES | U10: Yes | V10: 2 | W10: Joao | X10: Vaz | Y10: joao.beleza@anacom.pt | Z10: Ashya | AA10: Lane Spollen MODERATOR | AB10: ashya@broadbandeurope.eu | AE10: Yes | AG10: 2 | AH10: Joao | AI10: Vaz | AJ10: joao.beleza@anacom.pt | AK10: Ashya | AL10: Lane Spollen MODERATOR | AM10: ashya@broadbandeurope.eu | AQ10: answered on the first of july | AS10: Deadline to complete the form: 31 July. - REMINDER SENT 08-08 + 14/08 | AT10: Joao | AU10: Vaz | AV10: joao.beleza@anacom.pt | AW10: 351919291238 | AX10: October 15 11:30 to 12:30 CET | AY10: Yes | AZ10: I prefer to travel by plane | BA10: Ponta Delgada | BB10: 45943 | BC10: 0.375 | BD10: Ponta Delgada | BE10: 45945 | BF10: 0.70833333 | BG10: Yes | BH10: Travelling to and from Ponta Delgada (Azores) may involve a stopover in Lisbon. If there is no flight connection on the same day, I would like to request accommodation in Lisbon. | BI10: YES | CC10: =BW10+BX10+BY10 -> 0
AT11: Ashya | AU11: Lane Spollen MODERATOR | AV11: ashya@broadbandeurope.eu | AY11: No | BG11: No | BW11: 0 | BX11: 0
A12: 45945 | B12: 14:00 - 15:30 | C12: 45945 | D12: 45946 | E12: 2110 | F12: Advancing and monitoring circular economy lifestyles and policies in cities and regions. | G12: Cities building tomorrow | H12: Interactive session | I12: 21102359 | J12: Yes | K12: German Environment Agency | L12: Germany | N12: Jan Gimkiewicz; Mariann Szabo | O12: Jan.Gimkiewicz@uba.de; szabo.mariann@gtk.bme.hu | P12: German Environment Agency | Q12: Project Manager | S12: yes | T12: YES | U12: Yes | V12: 3 | W12: Jan | X12: Gimkiewicz | Y12: jan.gimkiewicz@uba.de | Z12: Mariann | AA12: Szabo | AB12: szabo.mariann@gtk.bme.hu | AC12: Iris | AD12: Kriikkula | AE12: iris.kriikkula@turku.fi | AF12: Yes | AG12: 3 | AH12: Jan | AI12: Gimkiewicz | AJ12: jan.gimkiewicz@uba.de | AK12: Mariann | AL12: Szabo | AM12: szabo.mariann@gtk.bme.hu | AN12: Iris | AO12: Kriikkula | AP12: iris.kriikkula@turku.fi | AQ12: We will try to confirm Speakers in July. | AT12: Jan | AU12: Gimkiewicz | AV12: jan.gimkiewicz@uba.de | AW12: +49 (0)340 2103 3305 | AX12: Wed 15/10/2025, 14:00 - 15:30 CET | AY12: Yes | AZ12: I prefer to travel by train | BA12: Leipzig | BB12: 45945 | BC12: early morning - session at 2pm | BD12: Leipzig | BE12: 45946 | BG12: Yes | BH12: My session is on 15 October afternoon, but I would like to travel to Brussels already on 14 October, as the journey is quite long and there is no adequate option to travel on 15 October and get to Brussels in time. However, I wish to extend my stay to attend other sessions as a participant. And I would like to avoid the strike on 14 October. Therefore, I would be grateful if I could travel already on 13 October. | BW12: 1 | CF12: Please confirm whether we can book the flight on the 13th (instead of 15th in the morning) and whether we could cover those extra nights or not The speaker coming from Leipzig (session 2110), for whom we agreed the following: "while the train is cheaper, it seems disproportionate to cover 3 nights for him when there is a flight option, in particular since the journey is above 400 km. Please offer the flight ticket with one night accommodation." is insisting that he wants to arrive on 13 October instead of the morning of the 15th. He says: "This would ensure a timely arrival without complications and it would give me the opportunity to attend other sessions as well." The travel agency has confirmed that the train on 13 October is cheaper than on the 15th. Can we therefore offer him travel from 13 to 15 October, informing him that he would need to cover both nights of accommodation in that case? | CG12: TRAVEX comment: Current prices show that train tickets 13-15 Oct. are 256€ cheaper than flying 15-16 Oct Shadi decision: while the train is cheaper it seems disproportionate to cover 3 nights for him when there is a flight option, in particular since the journey is above 400 km. Please offer the flight ticket with one night accommodation. Caroline: If it is possible to make the round trip by plane on the same day for his session, then the train would not have been our recommended option. That said, we can offer a round trip by train since it is cheaper. We could even consider covering one overnight stay, provided that the price difference between the plane and the train is enough to cover the cost of one night. Any additional night, however, would remain at his own expense.
AT13: Iris | AU13: Kriikkula | AV13: iris.kriikkula@turku.fi | AW13: 358405899485 | AX13: 15.10.2025, 14.00-15.30 | AY13: Yes | AZ13: I prefer to travel by plane | BA13: Turku | BB13: 45943 | BC13: 14-16 | BD13: Turku | BE13: 45946 | BF13: 10am-18 | BG13: Yes | BM13: Turku | BN13: Flight | BR13: Turku | CF13: 13-15 is possible but it makes a landing in Turku at 02.00am…which is not really suitable -> PRICE: 701.10 euro 13-16 is more suitable - PRICE: 673.10 -> if this option is selected, please confirm whether we should cover all the nights from13 to 16th. | CG13: Regarding the accommodation, we can agree to cover from the 13 to the 15 (given the particular case as no feasible flights are available on 15 AM and due to strike on 14 October)
AT14: Mariann | AU14: Szabo | AV14: szabo.mariann@gtk.bme.hu | AW14: +36706012632 | AX14: 15/10/2025 from 14:00 to 15:30 | AY14: Yes | AZ14: I prefer to travel by plane | BA14: Budapest | BB14: 45945 | BC14: 6:30 | BD14: Budapest | BE14: 45945 | BF14: 21:30 | BG14: Yes | BI14: YES | BJ14: YES | BK14: YES | BL14: YES | BM14: Budapest | BN14: Flight | BO14: 45943 | BP14: 0.75 | BQ14: SN2826 | BR14: Budapest | BS14: 45945 | BT14: 0.89583333 | BU14: FR4264 | BV14: 406.27 | BW14: 1 | BX14: 1 | BY14: 0 | BZ14: 45943 | CA14: 45945 | CC14: =BW14+BX14+BY14 -> 2
A15: 45944 | B15: 14:00 - 15:00 | C15: 45943 | D15: 45945 | E15: 2112 | F15: Let’s build the future in cities together — accelerating the climate transition through impactful, U!REKA European university collaboration | G15: Cities building tomorrow | H15: Workshop | J15: No | K15: Metropolia University of Applied Sciences | L15: Finland | N15: Mikael Vainio ; Liesbet Cosyn | O15: mikael.vainio@metropolia.fi ; liesbet.cosyn@hogent.be | P15: Metropolia University of Applied Sciences | Q15: Representative | R15: Iina Oilinki - City of Helsinki - Director - - ; Filip van de Velde - City of Ghent - Expert - - ; Geleyn Meijer - Amsterdam University of Applied Sciences - President - - | S15: yes | T15: YES | U15: Yes | V15: 1 | W15: Iina | X15: Oilinki | Y15: iina.oilinki@hel.fi | Z15: - | AA15: - | AB15: - | AC15: - | AD15: - | AE15: - | AF15: Yes | AG15: 1 | AH15: Iina | AI15: Oilinki | AJ15: iina.oilinki@hel.fi | AK15: - | AL15: - | AM15: - | AN15: - | AO15: - | AP15: - | AQ15: Our speaker from the City of Helsinki, Iina Oilinki, would prefer a direct flight connection from Helsinki to Brussels. | AR15: positive | AS15: they would like t&a from the 13th to the 15th | AT15: Iina | AU15: Oilinki | AV15: iina.oilinki@hel.fi | AW15: 358-50-3461216 | AX15: 14.10.2025 14.00-15-00 | AY15: Yes | AZ15: I prefer to travel by plane | BA15: Helsinki | BB15: 45943 | BC15: afternoon (for example the Finnair at 16.40) | BD15: Helsinki | BE15: 45945 | BF15: mid morning (not before 8 am) for example the Finnair at 11.40 | BG15: Yes | BI15: YES | BJ15: YES | BK15: YES | BL15: YES | BM15: Helsinki | BN15: Flight | BO15: 45943 | BP15: 0.69444444 | BQ15: AY1545 | BR15: Helsinki | BS15: 45945 | BT15: 0.48611111 | BU15: AY1542 | BV15: 653.1 | BW15: 1 | BX15: 1 | BZ15: 45943 | CA15: 45945 | CC15: =BW15+BX15+BY15 -> 2 | CF15: 673,10€ - over budget | CG15: Shadi: ok | CH15: Approval received via email on 8 August
A16: 45945 | B16: 14:00 - 15:00 | C16: 45945 | D16: 45946 | E16: 2113 | F16: Cooperation for a Safer Tomorrow: Strengthening Security and Resilience Across Europe | G16: Cohesion and Growth for the Future | H16: Workshop | J16: No | K16: Interact Managing Authority | L16: Slovakia | N16: Jelena Stojovic ; Zaneta Chylova | O16: jelena.stojovic@interact.eu ; zaneta.chylova@interact.eu | P16: Interact | Q16: Representative | R16: Erwin SIWERIS - Interreg Europe - Programme Manager - - ; Wiktor Szydarowski - ESPON EGTC - Director - - ; Margit Tuennemann - URBACT Secretariat - Policy Officer - -
A17: 45945 | B17: 14:00 - 15:00 | C17: 45945 | D17: 45946 | E17: 2117 | F17: YOUTH 4 OUTERMOST REGIONS Final Event | G17: The Right to Stay: unlocking the potential of every territory | H17: Workshop | J17: No | K17: Startup Europe Regions Network | L17: Belgium | N17: Ana Catarino ; Luisa Marchionni | O17: ana.catarino@startupregions.eu ; luisa.marchionni@startupregions.eu; info@youth4outermostregions.eu | P17: Startup Europe Regions Network | Q17: Project Manager | R17: Daniel ALBUQUERQUE - European Commission - Expert - - ; German ESTEBAN - European Commission - Deputy Head of Unit - - ; Luisa Marchionni - Startup Europe Regions Network - Project Manager - - | S17: yes | T17: YES | U17: Yes | V17: 2 | W17: Soraia | X17: Rodrigues | Y17: Soraia.Rodrigues00@hotmail.com | Z17: Laurine | AA17: Marié | AB17: o.laurinemarie@gmail.com | AF17: Yes | AG17: 3 | AH17: Soraia | AI17: Rodrigues | AJ17: Soraia.Rodrigues00@hotmail.com | AK17: Laurine | AL17: Marié | AM17: o.laurinemarie@gmail.com | AN17: Noelia del Pino | AO17: Rodriguez Dominguez | AP17: noeliarodriguez1900@gmail.com; hola@b4c.es | AQ17: The speakers will be travelling from EU's outermost regions. | AS17: Email sent to confirm city/location | AT17: Soraia | AU17: Rodrigues | AV17: Soraia.Rodrigues00@hotmail.com | AW17: +351 912000151 | AX17: 15 october at 2 pm | AY17: Yes | AZ17: I prefer to travel by plane | BA17: Funchal, Madeira | BB17: 45943 | BD17: Funchal, Madeira | BE17: 45946 | BG17: Yes | BH17: Considering the national strike is planned for 14 October, I would prefer to travel on the 13th or 12 th of October. I only wish to stay for the time strictly necessary for the event (or a little bit more to know the city) . If possible, I would appreciate it if you could arrange a direct flight from Madeira to Brussels. I’m not sure what dates to request at this stage, as the event is still a bit far off. I would also be grateful if you could contact me or share the available flight options closer to the date, when travel arrangements are being prepared. If possible, I would appreciate it if you could contact me or share the available flight options closer to the date, or when travel arrangements are being prepared. Thank You so much | BI17: YES | BJ17: YES | BK17: YES | BL17: YES | BM17: Funchal (Madeira) | BN17: Flight | BO17: 45943 | BP17: 0.52430556 | BQ17: TP1688 | BR17: Funchal (Madeira) | BS17: 45946 | BT17: 0.49305556 | BU17: TP641-TP1691 | BW17: 1 | BX17: 1 | BY17: 1 | CF17: Please confirm whether we can book the flight on the 13th (instead of 15th in the morning) and whether we could cover the extra nights on 13 and 14 October | CG17: Shadi: Given the length of the journey we confirm we can cover the accommodation and travel from 13 to 16 AugustFInalis
AT18: Laurine | AU18: Marié | AV18: o.laurinemarie@gmail.com | AW18: 33685516610 | AX18: 15 october at 2 pm | AY18: Yes | AZ18: I prefer to travel by plane | BA18: Toulon (France) | BB18: 45945 | BC18: In the morning | BD18: Toulon | BE18: 45945 | BF18: In the morning | BG18: Yes | BH18: Considering the national strike is planned for 14 October, I would prefer to travel on the 13th of October | BY18: 0 | CF18: Please confirm whether we can book the flight on the 13th (instead of 15th in the morning) and whether we could cover the extra nights on 13 and 14 October Laurine is the speaker coming from Toulon. In her form, she indicated that she wanted to travel on 13 October instead of 15 October. However, after checking with Shadi, we agreed to offer her a round-trip on 15 October (since her session is at 2:00 pm that day and this option was feasible). SN3604 15OCT MRS 1 BRU 06:40 - 0825 SN3603 15OCT BRU MRS 1 21:10 – 22: 55 However, when the travel agency sent her the travel proposal, she replied saying that she insists on traveling on 13 October. We informed her that: "As your session is on 15 October at 2 pm, the strike does not affect your case. In addition, since there is an option to return on the same day after your session, no nights can be offered to you (we would only offer the night of 15 October if no return flight were available that same evening). Therefore, if you wish to arrive on 13 October (provided there is a flight at the same or lower cost than on 15 October), you would need to cover both the night of 13 and the night of 14 October yourself. Moreover, we would not arrange the booking for you and you would need to take care of it directly." Now the session organiser (Ana Caterino) has contacted us and said the following: "We were previously informed by the EU Regions Week Secretariat team of the possibility of traveling on 13 October, with an extra night secured for this purpose. As DG REGIO.A1 colleagues are already making arrangements for 14 October, I would like to kindly request that Laurine arrives on 13 October in order to join her colleagues and participate in the programme on 14 October." I still understand that, since she has the option to travel to Brussels and back on 15 October, we should not cover the extra nights and that we could only offer travel on 13 October if the flight on that day is equal to or cheaper than the flight on 15 October. Could you please confirm how we should proceed? | CG18: Shadi: Please offer a return travel for the same day 15 August SN3604 15OCT MRS 1 BRU 0640 0825 SN3603 15OCT BRU MRS 1 2110 2255 Price : 660€ Caroline: If a same-day return by plane is possible for her session, we would not have suggested the outbound travel on 13 October. However, we can offer it. We could cover one overnight stay if the fare difference between 13–15 October and a same-day return on 15 October is enough to cover the cost of one night. Any extra nights would remain at her expense.
AT19: Noelia del Pino | AU19: Rodriguez Dominguez | AV19: noeliarodriguez1900@gmail.com; hola@b4c.es | AW19: 34662431372 | AX19: 15 october at 2 pm | AY19: Yes | AZ19: I prefer to travel by plane | BA19: Las Palmas de Gran Canaria | BB19: 45943 | BC19: 0.33333333 | BD19: Las Palmas de Gran Canaria | BE19: 45945 | BF19: 0.75 | BG19: Yes | BH19: "Considerando que el paro nacional está previsto para el 14 de octubre, preferiría viajar el 13 de octubre". | BI19: YES | BJ19: YES | BK19: YES | BL19: YES | BM19: Las Palmas de Gran Canaria | BN19: Flight | BO19: 45943 | BP19: 10:25 | BQ19: VY 3005 | BR19: Las Palmas de Gran Canaria | BS19: 45945 | BT19: 18:05 | BU19: VY 8983 | BV19: €759.84 (TBC) | BW19: 1 | BX19: 1 | BY19: 0 | CF19: no flight available on the morning of the 15th that would allow her to arrive in time for her session. Therefore, she would need to arrive on the 13th and could return on the 15th after her session. The price of this flight is €759.84. Could you please confirm whether we can book this flight, and if so, whether we should cover the nights of October 13 and 14 (and “release” the night of the 15 we had initially planned for her)? | CG19: Agreed, thank you
A20: 45944 | B20: 14:00 - 15:00 | C20: 45943 | D20: 45945 | E20: 2124 | F20: Unlocking Regional Potential through European University Alliances: The Cases of BAUHAUS4EU and SUNRISE | G20: The Right to Stay: unlocking the potential of every territory | H20: Workshop | J20: No | K20: Hauts-de-France Regional Council | L20: France | N20: Romain Nivelle ; Annaelie Zapfe | O20: romain.nivelle@hautsdefrance.fr ; Annelie.Zapfe@tsk.thueringen.de | P20: Hauts-de-France Region | Q20: Director | R20: Thomas MIROW - TU Ilmenau - Head of Unit - - ; Joanna Daaboul - UTC - Head of Unit - - ; Andreas ZEINERT - UPJV - Project Manager - -
A21: 45945 | B21: 14:00 - 15:00 | C21: 45945 | D21: 45946 | E21: 2127 | F21: Women breaking barriers: gender-responsive twin transformation across regions | G21: Cohesion and Growth for the Future | H21: Workshop | I21: 21272163 | J21: Yes | K21: United Nations Development Programme | L21: Türkiye | N21: İrem Uzun ; Sedef Zağlıkılıç | O21: irem.uzun@undp.org ; sedef.zaglikilic@undp.org | P21: United Nations Development Programme | Q21: Representative | R21: Turkish Confederation of Employer Associations TİSK - Turkish Conferedation of Employer Associations - Director - - ; Hande Bayrak - MEXT Technology Center (MEXT) - Director - - ; Kısmet Deniz Çiftçi - United Nations Development Programme - Director - - | S21: yes | T21: YES | U21: Yes | V21: 3 | W21: İrem | X21: Uzun | Y21: irem.uzun@undp.org | Z21: Pelin | AA21: Öztürk Yudu | AB21: pozturk@tisk.org.tr | AC21: Mustafa Akan | AD21: Fazlıoğlu | AE21: mustafa.fazlioglu@eeas.europa.eu | AF21: Yes | AG21: 3 | AH21: İrem | AI21: Uzun | AJ21: irem.uzun@undp.org | AK21: Pelin | AL21: Öztürk Yudu | AM21: pozturk@tisk.org.tr | AN21: Mustafa Akan | AO21: Fazlıoğlu | AP21: mustafa.fazlioglu@eeas.europa.eu | AQ21: We had previously sent an email to clarify whether the T&A arrangement covers the moderator and coordinator, but since we haven’t received a response yet, we filled out the form in order not to miss the deadline. If this is not the case, we would appreciate it if you could kindly let us know. | AT21: İrem | AU21: Uzun | AV21: irem.uzun@undp.org | AW21: +90 535 971 7794 | AX21: 15/10/2025 14:00-15:00 | AY21: Yes | AZ21: I prefer to travel by plane | BA21: Ankara, Türkiye | BB21: 45943 | BC21: early morning on 15th of October if possible. If not departure date is 13th October | BD21: Ankara, Türkiye | BE21: 45946 | BF21: 15:00 | BG21: Yes | BH21: Although our session is scheduled for the afternoon of October 15, since we will be travelling from Ankara and there are no direct flights between Ankara and Brussels, we would prefer to travel on October 14— if it is also convenient for you. In addition, since we would like to attend the events taking place after our session on 15 October and plan to hold meetings with potential partners, would it be possible to arrange our return tickets for 16 October? In this case, we agree to cover the accommodation expenses for the extra night in Brussels on 15 October. | BY21: 0 | CC21: =BW21+BX21+BY21 -> 0 | CF21: no flight on the 15th morning - they should travel on the 13th | CG21: We confirm that we can cover accommodation for the extra nights for the two speakers (nights covered from 13 to 16)
AT22: Pelin | AU22: Öztürk Yudu | AV22: pozturk@tisk.org.tr | AW22: +90 530 312 48 84 | AX22: 15/10/2025 14:00-15:00 | AY22: Yes | AZ22: I prefer to travel by plane | BA22: Ankara, Türkiye | BB22: 45943 | BC22: 09:00 | BD22: Ankara, Türkiye | BE22: 45946 | BF22: 15:00 | BG22: Yes | BH22: Although our session is scheduled for the afternoon of October 15, since we will be travelling from Ankara and_x000D_ there are no direct flights between Ankara and Brussels, we would prefer to travel on October 14— if it is also_x000D_ convenient for you. In addition, since we would like to attend the events taking place after our session on 15_x000D_ October and plan to hold meetings with potential partners, would it be possible to arrange our return tickets for_x000D_ 16 October? In this case, we agree to cover the accommodation expenses for the extra night in Brussels on 15_x000D_ October. | BY22: 0 | CC22: =BW22+BX22+BY22 -> 0 | CF22: no flight on the 15th morning - they should travel on the 13th | CG22: We confirm that we can cover accommodation for the extra nights for the two speakers (nights covered from 13 to 16)
AT23: Deniz | AU23: Ciftci | AV23: deniz.ciftci@undp.org | AW23: 36706339119 | AX23: 2025. October 15. / 11:30 | AY23: Yes | AZ23: I prefer to travel by plane | BA23: Ankara, Türkiye | BB23: 45943 | BC23: 0.33333333 | BD23: Ankara, Türkiye | BE23: 45946 | BF23: 0.58333333 | BG23: NO - IMPORTANT - ACCOMMODATION NOT COVERED | BH23: Within the scope of the event, the ticket options for our other team members (İrem Hüda Uzun and Pelin Öztürk Yudu) were proposed as departure on 13 October and return on 16 October. In this regard, I kindly request that the same ticket options be proposed for me as well. | BY23: 0 | CC23: =BW23+BX23+BY23 -> 0 | CF23: Since the EEAS speaker was initially indicated but could not be covered as this did not align with the event’s guidelines, and given that the replacement has been proposed after the deadline, we are unfortunately unable to guarantee full coverage at this stage. What we can do is cover the travel ticket for the replacement, Ms. Deniz Ciftci. However, please note that the accommodation arrangements would need to be made and covered directly by you.
A24: 45945 | B24: 09:30 - 11:00 | C24: 45943 | D24: 45945 | E24: 2151 | F24: EU NEB Local Chapters: Shaping the Future of the New European Bauhaus at Local Level together – Participatory lab | G24: Cities building tomorrow | H24: Interactive session | J24: No | K24: EuroVértice | L24: Spain | N24: Nuria Prior Arce ; Alessandro Rancati | O24: nuria.prior@eurovertice.eu ; starglide@livepods.eu | P24: EuroVértice | Q24: Director-General | R24: Borut CINK - European Commission - JRC - Brussels - Representative - - ; Marcos ROS SEMPERE - European Parliament - - - - ; Paola VALANDRO - ART-ER Attrattività Ricerca Territorio - - - | S24: yes | T24: YES | U24: Yes | V24: 3 | W24: Maria | X24: Huertas Rubio | Y24: maria.huertas@eurovertice.eu | Z24: Paola | AA24: Valandro | AB24: paola.valandro@art-er.it | AC24: Patrik | AD24: Karlsson | AE24: patrik.karlsson.ryberg@ri.se | AF24: Yes | AG24: 3 | AH24: María | AI24: Huertas Rubio | AJ24: maria.huertas@eurovertice.eu | AK24: Paola | AL24: Valandro | AM24: paola.valandro@art-er.it | AN24: Patrik | AO24: Karlsson | AP24: patrik.karlsson.ryberg@ri.se | AQ24: no comment | AR24: positive | AS24: they would like to stay more and change their flight date | AT24: Maria | AU24: Huertas Rubio | AV24: maria.huertas@eurovertice.eu | AW24: 34636244484 | AX24: Wed 15/10/2025, 09:30 - 11:00 CET | AY24: Yes | AZ24: I prefer to travel by plane | BA24: Alicante | BB24: 45943 | BC24: 17.3 | BD24: Alicante | BE24: 45946 | BF24: 21.15 | BG24: Yes | BH24: I wish to extend my stay to attend other sessions as a participant if possible. Additional nights on 13th and 15th will be covered on my own. | BI24: YES | BM24: Alicante | BN24: Flight | BR24: Alicante | CF24: Please confirm whether we can book the return flight on the 16 (instead of 15th). He says he would cover the extra night on the 15th
AT25: Paola | AU25: Valandro | AV25: paola.valandro@art-er.it | AW25: 393382219275 | AX25: 15/10/2025 - 9:30 - 11:00 | AY25: Yes | AZ25: I prefer to travel by plane | BA25: Bologna (Italy) | BB25: 45943 | BC25: 0.60416667 | BD25: Brussels | BE25: 45945 | BF25: 0.66666667 | BG25: Yes | BH25: To avoid issues with the national strike planned for 14 October in Belgium I will travel the 13th, so I need additional night in Brussels. Thanks | BI25: YES | BJ25: YES | BK25: YES | BL25: YES | BM25: Bologna (Italy) | BN25: Flight | BO25: 45943 | BP25: 0.77083333 | BQ25: az7636 | BR25: Bologna (Italy) | BS25: 45945 | BT25: 0.66666667 | BU25: az7637 | BV25: 398.2 | BW25: 1 | BX25: 1 | BZ25: 45943 | CA25: 45945 | CC25: =BW25+BX25+BY25 -> 2
AT26: Patrik | AU26: Karlsson Ryberg | AV26: patrik.karlsson.ryberg@ri.se | AW26: 46730452338 | AX26: the 15th October, 9:30-11:00 | AY26: Yes | AZ26: I prefer to travel by plane | BA26: Stockholm | BB26: 45943 | BC26: 0.5 | BD26: Stockholm | BE26: 45945 | BF26: 0.75 | BG26: Yes | BI26: YES | BJ26: YES | BK26: YES | BL26: YES | BM26: Stockholm | BN26: Flight | BO26: 45943 | BP26: 0.53472222 | BQ26: SN2292 | BR26: Stockholm | BS26: 45945 | BT26: 0.82986111 | BU26: SK1590 | BV26: 388.93 | BW26: 1 | BX26: 1 | BZ26: 45943 | CA26: 45945 | CC26: =BW26+BX26+BY26 -> 2
A27: 45944 | B27: 14:00 - 15:00 | C27: 45943 | D27: 45945 | E27: 2155 | F27: Choosing Europe and its regions: Addressing brain drain of scientific minds in Europe & attracting talents from oversees | G27: The Right to Stay: unlocking the potential of every territory | H27: Workshop | J27: No | K27: European Commission - DG RTD | L27: Belgium | N27: Chiara Aprea ; Eszter Wirth | O27: Chiara.APREA@ec.europa.eu; Eszter.Wirth@cor.europa.eu | P27: European Commission | Q27: DG RTD - Representative | R27: Magda DE CARLI - European Commission - DG RTD - Deputy Director - - ; Emil Boc - Cluj-Napoca City - Mayor - - | S27: yes | T27: YES | U27: Yes | V27: 1 | W27: Gabriele | X27: Marzano | Y27: gabriele.marzano@regione.emilia-romagna.it | AF27: Yes | AG27: 1 | AH27: Gabriele | AI27: Marzano | AJ27: gabriele.marzano@regione.emilia-romagna.it | AQ27: Only 1 speaker may need travel and accommodation coverage. The name of the speaker is yet to be confirmed. | AT27: Gabriele | AU27: Marzano | AV27: gabriele.marzano@regione.emilia-romagna.it | AW27: 00393358285087 | AX27: Tue 14/10/2025, 14:00 - 15:00 CET | AY27: Yes | AZ27: I prefer to travel by plane | BA27: Bologna (IT) | BB27: 45943 | BC27: h. 18.30 | BD27: Bologna | BE27: 45945 | BG27: Yes | BH27: In order to prevent the risk of delaying my presence to the session due at 14.00h on the 14th of October, because of national strikes, I would prefer 1) to reach Brussels the day before (i.e. Brussels Airlines from Bologna to Brussels (h. 18.30 - 20.15); 2) stay the night btw 13th and 14th Oct; 3) be already in the morning at the events; 4) leaving in the evening by airplane (i.e. BRU h. 18.55 - FCO - BLQ h. 22.45). I motivate this request for prevening any risk of facing impediments for strikes in the morning of the 14th October. Thanks. Gabriele Marzano | BI27: YES | BJ27: YES | BK27: YES | BL27: YES | BM27: Bologna (IT) | BN27: Flight | BO27: 45943 | BP27: 0.77083333 | BQ27: az7636 | BR27: Bologna (IT) | BT27: 0.78819444 | BU27: az165-1321 | BV27: 412.96 | BW27: 1 | BX27: 1 | BZ27: 45943 | CA27: 45945 | CC27: =BW27+BX27+BY27 -> 2
A28: 45944 | B28: 09:30 - 10:30 | C28: 45943 | D28: 45945 | E28: 2158 | F28: Territorial truths: What the data say about Europe's cohesion and competitiveness | G28: Cohesion and Growth for the Future | H28: Workshop | J28: No | K28: European Commission - Eurostat | L28: Luxembourg | N28: Reka Fodor ; Mate Farkas | O28: Reka.FODOR@ec.europa.eu ; Mate.FARKAS@ec.europa.eu | P28: European Commission | Q28: Eurostat - Assistant | R28: Lewis DIJKSTRA - European Commission - DG JRC - Representative - - ; Teodora BRANDMUELLER - Eurostat - Deputy Head of Unit - - ; Rudiger Ahrend - Organisation for Economic Co-operation and Development - Representative - - | S28: yes | T28: YES | V28: 1 | W28: Rudiger | X28: Ahrend | Y28: Rudiger.Ahrend@oecd.org | AF28: Yes | AG28: 1 | AH28: Rudiger | AI28: Ahrend | AJ28: Rudiger.Ahrend@oecd.org | AS28: Deadline to complete the form: 5 August - REMINDER SENT 08-08 | AT28: Rudiger | AU28: Ahrend | AV28: Rudiger.Ahrend@oecd.org | AW28: 685483996 | AX28: 14 October, 9.30 | AY28: Yes | AZ28: I prefer to travel by train | BA28: Paris | BB28: 45943 | BC28: 9.12 am | BD28: Paris | BE28: 45945 | BF28: 17.16 | BH28: I would like to stay beyond the 14th to participate in other sessions. I understand that the second night may not be covered. | BI28: YES | BM28: Paris | BN28: Train | BR28: Paris
A29: 45945 | B29: 14:00 - 15:30 | C29: 45945 | D29: 45946 | E29: 2192 | F29: Hackathon: Shaping a smart and sustainable tourism strategy in the Mediterranean together | G29: Cohesion and Growth for the Future | H29: Interactive session | I29: 219224972658 | J29: Yes | K29: Interreg Italy - France Maritime | L29: Italy | N29: Filippo Giabbani ; Maura Isetto ; Franceesca D'Angelo | O29: marittimo1420@regione.toscana.it ; mauraisetto11@gmail.com; francesca.dangelo@regione.toscana.it | P29: Interreg Italy | Q29: France Maritime - Programme Manager | R29: Filippo Giabbani - Interreg Italy - France Maritime - Programme Manager - - ; Joseph Park - NECSTouR - Representative - - ; ROSA ESCAMILLA - Interact - - - - | S29: yes | T29: YES | U29: Yes | V29: 2 | W29: ALEJANDRO | X29: LA FARGA MARTINEZ | Y29: lafarga_ale@gva.es | Z29: SILVIA | AA29: COMIATI | AB29: silvia.comiati@regione.veneto.it | AF29: Yes | AG29: 2 | AH29: ALEJANDRO | AI29: LA FARGA MARTINEZ | AJ29: lafarga_ale@gva.es | AK29: SILVIA | AL29: COMIATI | AM29: silvia.comiati@regione.veneto.it | AQ29: no comment | AS29: Deadline to complete the form: 30 July - REMINDER SENT 08-08 | AT29: ALEJANDRO | AU29: LA FARGA MARTINEZ | AV29: lafarga_ale@gva.es | AW29: +34659557133 | AX29: 15/10/2025 14:00 | AY29: Yes | AZ29: I prefer to travel by plane | BA29: Valencia, Spain | BB29: 45943 | BC29: morning | BD29: Valencia, Spain | BE29: 45946 | BF29: afternoon | BG29: Yes | BH29: I am also part of the organising team of the stand 251960: transnational cooperation: building solidarity, driving synergies and delivering change; and my Programme (Interreg NEXT MED) is funding the NAWAMED project, which is finalist at the Regiostars Awards. We expect to attend the REGIOSTARS ceremony. Given all this. I need to travel to Brussels the 13th to be at the stand and come back the 16th to attend the ceremony. Thanks | BI29: YES | BM29: Valencia, Spain | BN29: Flight | BR29: Valencia, Spain | CF29: He is also part of a stand. Please confirm whether we can book his flights from the 13th to the 16th instead of 15 to 16th. PLease also confirm whether we will cover the extra nights or not | CG29: Approved from 13 to 16th - nights covered
AT30: SILVIA | AU30: COMIATI | AV30: silvia.comiati@regione.veneto.it | AW30: +39 338 496 3190 | AX30: 15/10/2025 at 14.00 | AY30: Yes | AZ30: I prefer to travel by plane | BA30: Venice | BB30: 45943 | BC30: 6.55 | BD30: Venice | BE30: 45945 | BF30: 21.2 | BG30: Yes | BH30: The cost of the flight on Monday 13/10 and Tuesday 14/10 is the same and I will take care of covering the hotel night for 13/10 | BI30: YES | BJ30: YES | BK30: YES | BL30: YES | BM30: Venice | BN30: Flight | BO30: 45943 | BP30: 0.28819444 | BQ30: sn3208 | BR30: Venice | BS30: 45945 | BT30: 0.88888889 | BU30: sn3207 | BV30: 383.13 | BY30: 0 | CC30: =BW30+BX30+BY30 -> 0 | CF30: Check if there is a flight on the 15th. IF YES -> If the fllight on the 13th has the same price or below she can travel. Accommodation at her own exp on 13 and 14 IF THERE IS NO FLIGHT ON 15TH early morning, please inform us
A31: 45945 | B31: 11:30 - 13:00 | C31: 45943 | D31: 45945 | E31: 2243 | F31: Participatory Lab: empowering communities through inclusive renovation and regional sustainability | G31: The Right to Stay: unlocking the potential of every territory | H31: Interactive session | I31: 22432635 | J31: Yes | K31: Steinbeis Europa Zentrum | L31: Germany | N31: Pia Burkhardt ; Siora Keller | O31: Ramojus.REIMERIS@ec.europa.eu ; Solange.MIFSUD@ec.europa.eu | P31: Steinbeis Europa Zentrum | Q31: Representative | R31: Mara Oprea - Institute for European Energy and Climate Policy - Expert - - ; Bernardo Xavier - Just a Change - Expert - - ; David Ferge - Th!nk Europe - Expert - - | S31: yes | T31: YES | U31: Yes | V31: 2 | W31: Clara | X31: Tripodi | Y31: clara.tripodi@justachange.pt | Z31: David | AA31: Ferge | AB31: david.ferge@fdm-ius.eu | AF31: Yes | AG31: 2 | AH31: Clara | AI31: Tripodi | AJ31: clara.tripodi@justachange.pt | AK31: David | AL31: Ferge | AM31: david.ferge@fdm-ius.eu | AP31: geral@mediotejo21.net | AQ31: Can we adapt in case the speaker changes? | AS31: BUDAPEST | AT31: Clara | AU31: Tripodi | AV31: clara.tripodi@justachange.pt | AW31: 351920403739 | AX31: 15th Oct at 11:30 CEST | AY31: Yes | AZ31: I prefer to travel by plane | BA31: Lisbon | BB31: 45943 | BC31: no preferences | BD31: Lisbon | BE31: 45945 | BF31: Later afternoon/Evening | BG31: Yes | BI31: YES | BJ31: YES | BK31: YES | BL31: YES | BM31: Lisbon | BN31: Flight | BO31: 45943 | BP31: 0.47222222 | BQ31: TP642 | BR31: Lisbon | BS31: 45945 | BT31: 0.87152778 | BU31: TP645 | BV31: 341.32 | BW31: 1 | BX31: 1 | BZ31: 45943 | CA31: 45945 | CC31: =BW31+BX31+BY31 -> 2
AT32: David | AU32: Ferge | AV32: david.ferge@fdm-ius.eu | AW32: 36706339119 | AX32: 13 - 15 Oct 11:30 CEST.N/A | AY32: Yes | AZ32: I prefer to travel by plane | BA32: Budapest | BB32: 45943 | BC32: Early morning or early afternoon | BD32: Budapest | BE32: 45945 | BF32: Afternoon or evening | BG32: Yes | BI32: YES | BJ32: YES | BK32: YES | BL32: YES | BW32: 1 | BX32: 1 | BZ32: 45943 | CA32: 45945
A33: 45944 | B33: 14:00 - 15:30 | C33: 45943 | D33: 45945 | E33: 2244 | F33: Regulatory Sandboxes in Action: Empowering Regions for Smarter Innovation | G33: Cohesion and Growth for the Future | H33: Interactive session | J33: No | K33: Joint Research Centre | L33: Italy | N33: Ramojus Reimeris ; Solange Mifsud | O33: Ramojus.REIMERIS@ec.europa.eu ; Solange.MIFSUD@ec.europa.eu | P33: European Commission | Q33: DG JRC - Representative | R33: Tatiana Fernández Sirera - Government of Catalonia - Head of Unit - - ; Johanna Dahl - Regional Council of Ostrobothnia - Expert - - | S33: yes | T33: YES | U33: Yes | V33: 3 | W33: Tatiana | X33: Fernández Sirera | Y33: t.fernandez@gencat.cat | Z33: Johanna | AA33: Dahl | AB33: Johanna.Dahl@obotnia.fi | AC33: Rosvaldas | AD33: Krušna | AE33: RKrusna@lb.lt | AF33: Yes | AG33: 3 | AH33: Tatiana | AI33: Fernández Sirera | AJ33: t.fernandez@gencat.cat | AK33: Johanna | AL33: Dahl | AM33: Johanna.Dahl@obotnia.fi | AN33: Rosvaldas | AO33: Krušna | AP33: RKrusna@lb.lt | AQ33: answered on the first of july | AS33: Deadline to complete the form: 30 July REMINDER SENT 08-08 Johanna has been replaced by Mats Brandt on13 August - approved by the client - form sent and deadline on Friday 15 August | AT33: Tatiana | AU33: Fernández Sirera | AV33: t.fernandez@gencat.cat | AW33: 34687494773 | AX33: 14/10/2025 14h - 15.30 h | AY33: Yes | AZ33: I prefer to travel by plane | BA33: Barcelona | BB33: 45943 | BC33: Afternoon | BD33: Barcelona | BE33: 45945 | BG33: Yes | BI33: YES | BJ33: YES | BK33: YES | BL33: YES | BM33: Barcelona | BN33: Flight | BO33: 45943 | BP33: 0.63194444 | BQ33: sn3707 | BR33: Barcelona | BS33: 45945 | BT33: 0.39930556 | BU33: sn3697 | BV33: 377.9 | BW33: 1 | BX33: 1 | BZ33: 45943 | CA33: 45945 | CC33: =BW33+BX33+BY33 -> 2
AT34: Mats | AU34: Brandt | AV34: mats.brandt@obotnia.fi | AW34: +358444934576 | AX34: 14.10.2025 14:00-15:30 | AY34: Yes | AZ34: I prefer to travel by plane | BA34: Vaasa | BB34: 13.10.2025 | BC34: 0.73263889 | BD34: Vaasa | BE34: 15.10.2025 | BF34: 0.79513889 | BG34: Yes | CF34: Mats Brandt – He is a speaker coming from Vaasa, and the travel agency has informed us that his Vaasa – Helsinki – Brussels round-trip ticket is over budget: €698.56. Could you please confirm if we can book it? | CG34: 20/08 : confirmed by Caroline | CH34: difference in price is only 50€
AT35: Rosvaldas | AU35: Krušna | AV35: RKrusna@lb.lt | AW35: 37069117792 | AX35: Tue 14/10/2025, 14:00 - 15:30 CET | AY35: Yes | AZ35: I prefer to travel by plane | BA35: Vilnius | BB35: 45943 | BC35: No preference | BD35: Vilnius | BE35: 45945 | BF35: No preference | BG35: Yes | BI35: YES | BJ35: YES | BK35: YES | BL35: YES | BM35: Vilnius | BN35: Flight | BO35: 45943 | BP35: 0.77777778 | BQ35: BT5371 | BR35: Vilnius | BS35: 45945 | BT35: 0.40625 | BU35: BT602 | BV35: 397.53 | BW35: 1 | BX35: 1 | BZ35: 45943 | CA35: 45945 | CC35: =BW35+BX35+BY35 -> 2
A36: 45945 | B36: 11:30 - 12:30 | C36: 45943 | D36: 45945 | E36: 2291 | F36: Safer Cities and Neighbourhoods through Public Space Design - Interactive Workshop for Future Cooperation and Expansion of Safer Cities Across Europe | G36: Cities building tomorrow | H36: Workshop | J36: No | K36: Innoarch, Innovation in architecture and Urban Planning | L36: Norway | N36: Isabel Ruiz Lopez ; Mads Bruun Høy | O36: isabel@grape.no ; mads@era.as | P36: Innoarch, Innovation in architecture and Urban Planning | Q36: Secretary - General | R36: Christina Thomassen Rooth - Oslo Police - Officer - - ; Marie Herping Abrahamsen - City of Copenhagen - Project Manager - - ; Magnus Lindgren - Safer Sweden Foundation - Secretary-General - - | S36: Yes | T36: YES | U36: Yes | V36: 3 | W36: Isabel | X36: Ruiz López | Y36: isabel@grape.no | Z36: Mads | AA36: Bruun Høy | AB36: mads@era.as | AC36: Christina | AD36: Thomassen Rooth | AE36: christina.thomassen.rooth@politiet.no | AF36: Yes | AG36: 3 | AH36: Isabel | AI36: Ruiz López | AJ36: isabel@grape.no | AK36: Mads | AL36: Bruun Høy | AM36: mads@era.as | AN36: Christina | AO36: Thomassen Rooth | AP36: christina.thomassen.rooth@politiet.no | AQ36: No comment | AT36: Isabel | AU36: Ruiz López | AV36: isabel@grape.no | AW36: 4796826316 | AX36: 13.10/14.10/15.10 | AY36: Yes | AZ36: I prefer to travel by plane | BA36: Oslo | BB36: 45943 | BC36: Early in the morning (Or 12.10.25 at the evening) | BD36: Alicante | BE36: 45945 | BF36: Late in the evening | BG36: Yes | BH36: I am also coordinating a parallel event organized by the Oslo Region Office on 13 October 2025 at 17:00. In addition, I will be participating as an external contributor at an event on 15 October 2025 at 09:30. I kindly ask you to take these events into consideration as well. Looking forward! | BI36: YES | BJ36: YES | BK36: YES | BL36: YES | BM36: Oslo | BN36: Flight | BO36: 45943 | BP36: 0.28125 | BQ36: sn2288 | BR36: Alicante | BS36: 45945 | BT36: 0.86111111 | BU36: vy1335 | BV36: 353.12 | BW36: 1 | BX36: 1 | BZ36: 45943 | CA36: 45945 | CC36: =BW36+BX36+BY36 -> 2
AT37: Mads | AU37: Bruun Høy | AV37: mads@era.as | AW37: 4792823204 | AX37: 15-10-2025 1130-1230 | AY37: Yes | AZ37: I prefer to travel by plane | BA37: Oslo | BB37: 45943 | BC37: Early in the morning | BD37: Oslo | BE37: 45945 | BF37: Late in the evening | BG37: Yes | BH37: nut allergy | BI37: YES | BJ37: YES | BK37: YES | BL37: YES | BM37: Oslo | BN37: Flight | BO37: 45943 | BP37: 0.28125 | BQ37: sn2288 | BR37: Oslo | BS37: 45945 | BT37: 0.87152778 | BU37: sn2287 | BV37: 356.12 | BW37: 1 | BX37: 1 | BZ37: 45943 | CA37: 45945 | CC37: =BW37+BX37+BY37 -> 2
AT38: Christina | AU38: Thomassen Rooth | AV38: christina.thomassen.rooth@politiet.no | AW38: 004740434545 | AX38: 14.10.25 | AY38: Yes | AZ38: I prefer to travel by plane | BA38: Oslo airport | BB38: 45943 | BC38: late evening | BD38: oslo airport | BE38: 45945 | BF38: evening | BG38: Yes | BI38: YES | BJ38: YES | BK38: YES | BL38: YES | BM38: Oslo | BN38: Flight | BO38: 45943 | BP38: 0.34722222 | BQ38: SK4743 | BR38: Oslo | BS38: 45945 | BT38: 0.87152778 | BU38: SN2287 | BV38: 320.96 | BW38: 1 | BX38: 1 | BZ38: 45943 | CA38: 45945 | CC38: =BW38+BX38+BY38 -> 2
A39: 45945 | B39: 09:30 - 11:00 | C39: 45943 | D39: 45945 | E39: 2304 | F39: How to make urban resilience work? City case studies and the role of research & innovation from DUT Partnership and URBACT | G39: Cities building tomorrow | H39: Interactive session | I39: Fegtc | J39: No | K39: AustriaTech GmbH | L39: Austria | N39: Maximilian Jäger ; Kristijan Radojcic | O39: maximilian.jaeger@austriatech.at ; k.radojcic@urbact.eu | P39: AustriaTech GmbH | Q39: Expert | R39: Mickaëlle Vergnaud - Bordeaux Metropolis - Head of Unit - - ; Merlin Pitz - - - - | S39: yes | T39: DO NOT NEED COVERAGE | U39: No, my speakers do not need coverage | AF39: No, my speakers do not need accommodation coverage | AQ39: no comment
A40: 45944 | B40: 11:30 - 13:00 | C40: 45943 | D40: 45945 | E40: 2314 | F40: Leveraging reconstruction and EU accession for regional development in Ukraine | G40: Cohesion and Growth for the Future | H40: Interactive session | I40: 205523142647 | J40: Yes | K40: EasyBusiness | L40: Ukraine | N40: Yaroslav Zhydyk ; Ljubica Kosheliuk | O40: yaroslav.zhydyk@easybusiness.in.ua ; ljubica.kosheliuk@giz.de | P40: EasyBusiness | Q40: Head of Unit | R40: Ambre Maucorps - The Vienna Institute for International Economic Studies - - - ; Yaroslav Zhydyk - EasyBusiness - Head of Unit - - ; Ljubica Kosheliuk - Deutsche Gesellschaft für Internationale Zusammenarbeit (GIZ) - Project Manager - - | S40: yes | T40: YES | U40: Yes | V40: 2 | W40: Dmytro | X40: Lyvch | Y40: dlyvch@easybusiness.in.ua | Z40: Iryna | AA40: Mykulych | AB40: mykulych@ard-ukraine.org | AF40: Yes | AG40: 2 | AH40: Dmytro | AI40: Lyvch | AJ40: dlyvch@easybusiness.in.ua | AK40: Iryna | AL40: Mykulych | AM40: mykulych@ard-ukraine.org | AQ40: no comment | AR40: positive | AS40: Deadline to complete the form: 30 July - REMINDER SENT 08-08 | AT40: Dmytro | AU40: Lyvch | AV40: dlyvch@easybusiness.in.ua | AY40: Yes | BG40: Yes | BW40: 0 | BX40: 0
...

Sheet Stands
A1: STANDHOLDERS INFORMATION | AL1: STANDHOLDER PREFERENCES | BA1: FOLLOW-UP | BE1: Travel information - confirmed | BZ1: APPROVALS
A2: Date | B2: Estimated arrival date | C2: Estimated departure date | D2: Index unique | E2: Title | F2: Thematic clusters | G2: Format | H2: Merged sessions | I2: Merged lead? | J2: Lead partner organisation name | K2: Lead partner organisation country of origin | L2: Associated partners | M2: Coordinator | N2: Email address | O2: Company name | P2: Job title | Q2: Answered | R2: Form/reminder sent | S2: Do any of your project members require travel coverage? | T2: Number of speakers for travel | U2: Travel - Speaker 1 - Name | V2: Travel - Speaker 1 - Name + last name | W2: Travel - Speaker 1 - Email address | X2: Travel - Speaker 2 - Name | Y2: Travel - Speaker 2 - Name + last name | Z2: Travel - Speaker 2 - Email address | AA2: Do any of your project members require accommodation coverage? | AB2: Number of speakers for accommodation | AC2: Accomodation - Speaker 1 - Name | AD2: Accomodation - Speaker 1 - Last name | AE2: Accomodation - Speaker 1 - Email address | AF2: Accomodation - Speaker 2 - Name | AG2: Accomodation - Speaker 2 - Last name | AH2: Accomodation - Speaker 2 - Email address | AI2: Additional comments | AJ2: Email follow up - Responses | AK2: Comments VO | AL2: First Name | AM2: Last name | AN2: Email address | AO2: Phone number | AP2: Date and time of your speaking slot | AQ2: Travel needed | AR2: Preferred mode of transport | AS2: City of departure | AT2: Date of departure | AU2: Time of departure | AV2: Return city | AW2: Preferred date of return | AX2: Preferred time of return | AY2: Accommoation needed | AZ2: Additional comments | BA2: Agency sent proposal | BB2: Guest confirmed proposal | BC2: Travel booked | BD2: Travel tickets sent to guest | BE2: Origin City (to Brussels) | BF2: Flight/Train | BG2: Date of departure | BH2: Flight/Train time | BI2: Flight number/Train | BJ2: Return City (from Brussels) | BK2: Date of return | BL2: Flight/Train time | BM2: Flight number/Train | BN2: Flight/Train cost | BO2: Hotel rate 13/10, €, excl. VAT | BP2: Hotel rate 14/10, €, excl. VAT | BQ2: Hotel rate 15/10, €, excl. VAT | BR2: 45943 | BS2: 45944 | BT2: 45945 | BU2: Check-in date | BV2: Check out date | BW2: Hotel nights | BX2: Hotel cost, €, excl. VAT | BY2: Total cost, € | BZ2: Client's approval needed | CA2: Client's approval received | CB2: Approval reason
A3: 14/10 - 15/10 | B3: 45943 | C3: 45946 | D3: 1960 | E3: Transnational cooperation: building solidarity, driving synergies & delivering change | F3: Cohesion and Growth for the Future | G3: Stand | I3: No | J3: Interreg North-West Europe | K3: France | M3: Rania Balia ; Martin Heibel | N3: rania@nweurope.eu ; mheibel@regione.sardegna.it | O3: Interreg North - West Europe | P3: Representative | Q3: yes | R3: reminder sent - However, the two stand holders, who are project representatives, have not yet been fully confirmed. There's also a possibility that their travel and accommodation is already covered through a different session during the week. Currently, we cannot specify exactly who these two representatives will be. If we do not meet your travel and accommodation deadlines, please feel free to withdraw our request for coverage. | S3: Yes | T3: 2 | U3: TBC | V3: TBC | W3: TBC | X3: TBC | Y3: TBC | Z3: TBC | AA3: Yes | AB3: 2 | AC3: TBC | AD3: TBC | AE3: TBC | AF3: TBC | AG3: TBC | AH3: TBC | AI3: no comment | AL3: TBC | AM3: TBC | AN3: TBC | AQ3: YES | AY3: YES | BW3: =BR3+BS3+BT3 -> 0
AL4: TBC | AM4: TBC | AN4: TBC | AQ4: YES | AY4: YES | BW4: =BR4+BS4+BT4 -> 0
A5: 14/10 - 15/10 | B5: 45943 | C5: 45946 | D5: 2005 | E5: Cohesion and Growth for the Future-the role of the civil society | F5: Cohesion and Growth for the Future | G5: Stand | I5: No | J5: European Economic and Social Committee | K5: Belgium | M5: Graziella Dilkinska ; Georgios Meleas | N5: Graziella.Dilkinska@eesc.europa.eu ; Georgios.Meleas@eesc.europa.eu | O5: European Economic and Social Committee | P5: Assistant | BW5: =BR5+BS5+BT5 -> 0
A6: 14/10 - 15/10 | B6: 45943 | C6: 45946 | D6: 2024 | E6: Interreg Europe – How cooperation unlocks regional potential | F6: The Right to Stay: unlocking the potential of every territory | G6: Stand | I6: No | J6: Interreg Europe | K6: France | M6: Marie Soucasse; Vladimir Sestovic | N6: m.soucasse@interregeurope.eu; v.sestovic@policylearning.eu | O6: Interreg Europe Policy Learning Platform | P6: Representative | Q6: yes | R6: YES - especial case, not travel,2 accomodation | S6: No, my speakers do not need coverage | T6: 0 | AA6: Yes | AB6: 2 | AC6: Marie | AD6: Soucasse | AE6: m.soucasse@interregeurope.eu | AF6: Irma | AG6: ASTRAUSKAITE | AH6: i.astrauskaite@interregeurope.eu | AI6: no comment | AK6: LILLE, FRANCE | AL6: Marie | AM6: Soucasse | AN6: m.soucasse@interregeurope.eu | AO6: +33647675364 | AP6: N/A | AQ6: NO | AT6: 45943 | AW6: 45946 | AY6: YES | BA6: YES | BB6: YES | BC6: YES | BD6: YES | BE6: Lille | BF6: TRAIN | BG6: TRAIN | BH6: TRAIN | BI6: TRAIN | BJ6: Lille | BK6: TRAIN | BL6: TRAIN | BM6: TRAIN | BN6: TRAIN | BR6: 1 | BS6: 1 | BT6: 1 | BU6: 13/010/2025 | BV6: 45946 | BW6: =BR6+BS6+BT6 -> 3 | BZ6: Marie and Irma, both standholders who only need accommodation (and not travel), have confirmed that they will come by train from Lille. Could you please confirm whether we can therefore cover both nights, 13 and 14 October, since they are not coming by car? (we discussed this stand the other day) Marie and Irma, both standholders who only need accommodation, have been informed that we will cover only the nights of 13 and 14 October and have told us the following: “The last train to Lille is at 18:16 on the evening of 15 October, and it is our understanding that we need to be at the stand until 18:00, which makes it difficult for us to catch our train on time.” Could you please confirm if, in this case, we can also book the night of 15 October for both of them? Please note that when making the estimates at the beginning of the process, these rooms for the 15th were planned for them and are still available. | CA6: confirmed | CB6: 20/08 Caroline : last departing train incompatible with stand schedule
AL7: Irma | AM7: Astrauskaite-Denis | AN7: i.Astrauskaite@interregeurope.eu | AO7: +33623408961 | AP7: N/A | AQ7: NO | AT7: 45943 | AW7: 45946 | AY7: YES | BA7: YES | BB7: YES | BC7: YES | BD7: YES | BE7: Lille | BF7: TRAIN | BG7: TRAIN | BH7: TRAIN | BI7: TRAIN | BJ7: Lille | BK7: TRAIN | BL7: TRAIN | BM7: TRAIN | BN7: TRAIN | BR7: 1 | BS7: 1 | BT7: 1 | BU7: 13/010/2025 | BV7: 45946 | BW7: =BR7+BS7+BT7 -> 3 | BZ7: Marie and Irma, both standholders who only need accommodation (and not travel), have confirmed that they will come by train from Lille. Could you please confirm whether we can therefore cover both nights, 13 and 14 October, since they are not coming by car? (we discussed this stand the other day) Marie and Irma, both standholders who only need accommodation, have been informed that we will cover only the nights of 13 and 14 October and have told us the following: “The last train to Lille is at 18:16 on the evening of 15 October, and it is our understanding that we need to be at the stand until 18:00, which makes it difficult for us to catch our train on time.” Could you please confirm if, in this case, we can also book the night of 15 October for both of them? Please note that when making the estimates at the beginning of the process, these rooms for the 15th were planned for them and are still available. | CA7: confirmed | CB7: 20/08 Caroline : last departing train incompatible with stand schedule
A8: 14/10 - 15/10 | B8: 45943 | C8: 45946 | D8: 2066 | E8: Have Your Say Portal | F8: Cohesion and Growth for the Future | G8: Stand | I8: No | J8: European Commission - Secretariat General | K8: Belgium | M8: Corina - Luciana Pirleci ; Carlos Perez-Padilla | N8: Corina-Luciana.PIRLECI@ec.europa.eu ; carlos.perez-padilla@ec.europa.eu | O8: European Commission | P8: Secretariat General - Representative | BW8: =BR8+BS8+BT8 -> 0
